Workbook

Sheet README
A1: Testco Industries plc (TSTC) — DCF valuation model
A3: Built | B3: 2026-10-17
A4: Currency | B4: USD
A5: Units | B5: millions
A6: Fiscal year end | B6: 31 December
A7: Generated by | B7: Financopedia build_model.py
A9: Colour key | B9: Blue = input you can change · Black = formula · Amber italic = estimated input
A10: Structure | B10: Every figure outside INPUTS and HISTORICALS is a formula. Change an input, the model moves.
A11: CHECKS tab | B11: Live assertions recomputing the model's identities. All must read PASS.
A12: History | B12: 10 reported years; see the statistics block on HISTORICALS for the range each assumption sits in
A13: Forecast | B13: 7 years, then a terminal value
A14: Discounting | B14: First period is 0.45 years from the valuation date; 1.00 is year-end, 0.50 the mid-year convention
A15: WACC | B15: Derived on the WACC tab — peer betas unlevered and re-levered, a Blume-adjusted regression beta, an equity risk premium from the market record, and the cost of debt from interest actually paid
... A21: Not advice | B21: Not financial advice and not produced by a licensed advisor. Assumptions are estimates and will be wrong to some degree; the sensitivity tab exists to show by how much.

Sheet INPUTS
A1: INPUTS — the only assumptions in the model
A2: Blue = input. Amber italic = estimated. Black = calculated from the cells above.
A3: Assumption | B3: Value | C3: Unit | I3: Basis / source
A4: Tax rate | B4: 0.21 | C4: % | I4: FY2025 effective rate per the 10-K tax footnote
A5: Risk-free rate | B5: =WACC!B56 | C5: % | I5: Derived on the WACC tab
A6: Equity risk premium | B6: =WACC!B57 | C6: % | I6: Derived on the WACC tab
A7: Beta | B7: =WACC!B23 | C7: x | I7: Derived on the WACC tab
A8: Cost of debt (pre-tax) | B8: =WACC!B62 | C8: % | I8: Derived on the WACC tab
A9: Debt weight of capital | B9: =WACC!B69 | C9: % | I9: Derived on the WACC tab
A10: WACC (calculated) | B10: =WACC!B70 | C10: % | I10: Derived on the WACC tab from the peer set, the regression beta, the market record and interest actually paid
A11: Terminal growth rate | B11: 0.025 | C11: % | I11: Below long-run US nominal GDP growth
A12: Exit EV/EBITDA multiple | B12: 11 | C12: x | I12: ESTIMATE: peer median EV/EBITDA, cross-check only
A13: Net debt | B13: 1150 | C13: millions | I13: Total debt less cash, FY2025 balance sheet
A14: Shares outstanding | B14: 420 | C14: millions | I14: Diluted weighted average shares, FY2025 10-K
A15: Current share price | B15: 21.4 | C15: millions | I15: LSE close, 2026-10-16
A16: Sensitivity: WACC step | B16: 0.005 | C16: %
A17: Sensitivity: x-axis step | B17: 0.0025 | C17: %
A18: First period (years from valuation date) | B18: 0.45 | C18: x | I18: Valuation date 2026-10-17; 0.45 of FY2026 remains to the 31 December year end
A19: Scenario growth shift (+/-) | B19: 0.02 | C19: % | I19: ESTIMATE: +/-2pp on the growth path, roughly the spread of broker forecasts
A21: Driver | B21: Y1 | C21: Y2 | D21: Y3 | E21: Y4 | F21: Y5 | G21: Y6 | H21: Y7 | I21: Basis / source
A22: Revenue growth | B22: =SEGMENTS!L11 | C22: =SEGMENTS!M11 | D22: =SEGMENTS!N11 | E22: =SEGMENTS!O11 | F22: =SEGMENTS!P11 | G22: =SEGMENTS!Q11 | H22: =SEGMENTS!R11 | I22: Built up on the SEGMENTS tab — growth is a consequence of the mix
A23: EBIT margin | B23: 0.214 | C23: 0.213 | D23: 0.212 | E23: 0.212 | F23: 0.211 | G23: 0.211 | H23: 0.21 | I23: ESTIMATE: held near the FY2023-FY2025 level, inside the 10-year range
A24: D&A (% of revenue) | B24: 0.049 | C24: 0.049 | D24: 0.049 | E24: 0.049 | F24: 0.049 | G24: 0.049 | H24: 0.049 | I24: 10-year average of D&A over revenue (10-K filings)
A25: Capex (% of revenue) | B25: 0.06 | C25: 0.059 | D25: 0.058 | E25: 0.057 | F25: 0.056 | G25: 0.055 | H25: 0.055 | I25: Y1 guided capex; later years fade to the 10-year average
A26: Net working capital (% of revenue) | B26: 0.1 | C26: 0.1 | D26: 0.1 | E26: 0.1 | F26: 0.1 | G26: 0.1 | H26: 0.1 | I26: ESTIMATE: 10-year average of NWC over revenue
A29: Peer (comparables cross-check) | B29: EV/EBITDA | C29: P/E | D29: Source
A30: Peer One | B30: 10.5 | C30: 18 | D30: exchange data, 2026-10-16
A31: Peer Two | B31: 12 | C31: 21.5 | D31: exchange data, 2026-10-16
A32: Peer Three | B32: 9.4 | C32: 16.2 | D32: exchange data, 2026-10-16

Sheet HISTORICALS
A1: HISTORICALS — 10 reported years, each figure with its filing
A2: Blue = as reported in the cited filing. Black = calculated from the rows above.
A3: Metric | B3: 2016 | C3: 2017 | D3: 2018 | E3: 2019 | F3: 2020 | G3: 2021 | H3: 2022 | I3: 2023 | J3: 2024 | K3: 2025 | L3: Source (filing, date)
A4: Revenue | B4: 2150 | C4: 2365 | D4: 2580 | E4: 2790 | F4: 2510 | G4: 2980 | H4: 3320 | I4: 3610 | J4: 3940 | K4: 4280 | L4: FY2016-FY2025 10-K filings; FY2025 filed 2026-02-14 (revenue)
A5: EBIT | B5: 367.7 | C5: 421 | D5: 469.6 | E5: 518.9 | F5: 356.4 | G5: 581.1 | H5: 667.3 | I5: 743.7 | J5: 827.4 | K5: 920.2 | L5: FY2016-FY2025 10-K filings; FY2025 filed 2026-02-14 (ebit)
A6: EBIT margin | B6: =B5/B4 | C6: =C5/C4 | D6: =D5/D4 | E6: =E5/E4 | F6: =F5/F4 | G6: =G5/G4 | H6: =H5/H4 | I6: =I5/I4 | ... K6: =K5/K4
A7: D&A | B7: 105.4 | C7: 115.9 | D7: 126.4 | E7: 136.7 | F7: 123 | G7: 146 | H7: 162.7 | I7: 176.9 | J7: 193.1 | K7: 209.7 | L7: FY2016-FY2025 10-K filings; FY2025 filed 2026-02-14 (da)
A8: Capex | B8: 133.3 | C8: 153.7 | D8: 157.4 | E8: 161.8 | F8: 102.9 | G8: 175.8 | H8: 209.2 | I8: 216.6 | J8: 228.5 | K8: 256.8 | L8: FY2016-FY2025 10-K filings; FY2025 filed 2026-02-14 (capex)
A9: Net working capital (balance) | B9: 215 | C9: 236.5 | D9: 258 | E9: 279 | F9: 251 | G9: 298 | H9: 332 | I9: 361 | J9: 394 | K9: 428 | L9: FY2016-FY2025 10-K filings; FY2025 filed 2026-02-14 (nwc_balance)
A10: Change in net working capital | B10: =NA() | C10: =C9-B9 | D10: =D9-C9 | E10: =E9-D9 | F10: =F9-E9 | G10: =G9-F9 | H10: =H9-G9 | I10: =I9-H9 | J10: =J9-I9 | K10: =K9-J9
A11: Unlevered FCF (derived) | B11: =NA() | C11: =C5*(1-INPUTS!$B$4)+C7-C8-C10 | D11: =D5*(1-INPUTS!$B$4)+D7-D8-D10 | E11: =E5*(1-INPUTS!$B$4)+E7-E8-E10 | F11: =F5*(1-INPUTS!$B$4)+F7-F8-F10 | G11: =G5*(1-INPUTS!$B$4)+G7-G8-G10 | H11: =H5*(1-INPUTS!$B$4)+H7-H8-H10 | I11: =I5*(1-INPUTS!$B$4)+I7-I8-I10 | J11: =J5*(1-INPUTS!$B$4)+J7-J8-J10 | K11: =K5*(1-INPUTS!$B$4)+K7-K8-K10
A12: Net PP&E | B12: 1182.5 | C12: 1300.8 | D12: 1419 | E12: 1534.5 | F12: 1380.5 | G12: 1639 | H12: 1826 | I12: 1985.5 | J12: 2167 | K12: 2354 | L12: FY2016-FY2025 10-K filings, net property plant and equipment
A15: What 10 years of history says
A16: Revenue CAGR over the period | B16: =((K4/B4)^(1/9))-1 | C16: Compare this with the projected growth on INPUTS
A17: EBIT margin — average | B17: =AVERAGE(B6:K6)
A18: EBIT margin — low | B18: =MIN(B6:K6) | C18: A projected margin below this has happened before; above the high has not
A19: EBIT margin — high | B19: =MAX(B6:K6)
A20: Capex as % of revenue — average | B20: =AVERAGE(B8:K8)/AVERAGE(B4:K4)
A21: Years revenue fell | B21: =SUMPRODUCT(--(C4:K4<B4:J4)) | C21: A model with no down years in a business that has had them is a choice

Sheet SEGMENTS
A1: SEGMENTS — the top line, built up
A2: Each segment on its own growth path. Group growth is then a consequence of the mix, not an assumption: a shift toward a faster segment lifts it without anyone asserting that it does.
A3: Segment | B3: 2016 | C3: 2017 | D3: 2018 | E3: 2019 | F3: 2020 | G3: 2021 | H3: 2022 | I3: 2023 | J3: 2024 | K3: 2025 | L3: 2026 | M3: 2027 | N3: 2028 | O3: 2029 | P3: 2030 | Q3: 2031 | R3: 2032
A4: Domestic | B4: 1118 | C4: 1206.2 | D4: 1290 | E4: 1367.1 | F4: 1305.2 | G4: 1400.6 | H4: 1527.2 | I4: 1624.5 | J4: 1733.6 | K4: 1840.4 | L4: =K4*(1+L14) | M4: =L4*(1+M14) | N4: =M4*(1+N14) | O4: =N4*(1+O14) | P4: =O4*(1+P14) | Q4: =P4*(1+Q14) | R4: =Q4*(1+R14)
A5: North America | B5: 559 | C5: 638.6 | D5: 722.4 | E5: 809.1 | F5: 652.6 | G5: 923.8 | H5: 1062.4 | I5: 1191.3 | J5: 1339.6 | K5: 1498 | L5: =K5*(1+L15) | M5: =L5*(1+M15) | N5: =M5*(1+N15) | O5: =N5*(1+O15) | P5: =O5*(1+P15) | Q5: =P5*(1+Q15) | R5: =Q5*(1+R15)
A6: Europe | B6: 301 | C6: 331.1 | D6: 361.2 | E6: 390.6 | F6: 351.4 | G6: 417.2 | H6: 464.8 | I6: 505.4 | J6: 551.6 | K6: 599.2 | L6: =K6*(1+L16) | M6: =L6*(1+M16) | N6: =M6*(1+N16) | O6: =N6*(1+O16) | P6: =O6*(1+P16) | Q6: =P6*(1+Q16) | R6: =Q6*(1+R16)
A7: Other markets | B7: 172 | C7: 189.1 | D7: 206.4 | E7: 223.2 | F7: 200.8 | G7: 238.4 | H7: 265.6 | I7: 288.8 | J7: 315.2 | K7: 342.4 | L7: =K7*(1+L17) | M7: =L7*(1+M17) | N7: =M7*(1+N17) | O7: =N7*(1+O17) | P7: =O7*(1+P17) | Q7: =P7*(1+Q17) | R7: =Q7*(1+R17)
A8: Total revenue | B8: =SUM(B4:B7) | C8: =SUM(C4:C7) | D8: =SUM(D4:D7) | E8: =SUM(E4:E7) | F8: =SUM(F4:F7) | G8: =SUM(G4:G7) | H8: =SUM(H4:H7) | I8: =SUM(I4:I7) | ... R8: =SUM(R4:R7)
A9: Reported revenue | B9: =HISTORICALS!B4 | C9: =HISTORICALS!C4 | D9: =HISTORICALS!D4 | E9: =HISTORICALS!E4 | F9: =HISTORICALS!F4 | G9: =HISTORICALS!G4 | H9: =HISTORICALS!H4 | I9: =HISTORICALS!I4 | ... K9: =HISTORICALS!K4
A10: Check (segments − reported) | B10: =B8-B9 | C10: =C8-C9 | D10: =D8-D9 | E10: =E8-E9 | F10: =F8-F9 | G10: =G8-G9 | H10: =H8-H9 | I10: =I8-I9 | ... K10: =K8-K9 | S10: Must be zero in every reported year, or a segment is missing
A11: Implied group growth | L11: =L8/K8-1 | M11: =M8/L8-1 | N11: =N8/M8-1 | O11: =O8/N8-1 | P11: =P8/O8-1 | Q11: =Q8/P8-1 | R11: =R8/Q8-1
A13: Growth assumptions by segment | S13: Basis / source
A14: Domestic | L14: 0.045 | M14: 0.042 | N14: 0.04 | O14: 0.038 | P14: 0.035 | Q14: 0.032 | R14: 0.03 | S14: Segment growth per the FY2025 annual report's outlook statement — FY2016-FY2025 annual reports, segment note
A15: North America | L15: 0.125 | M15: 0.112 | N15: 0.098 | O15: 0.085 | P15: 0.072 | Q15: 0.062 | R15: 0.055 | S15: Segment growth per the FY2025 annual report's outlook statement — FY2016-FY2025 annual reports, segment note
A16: Europe | L16: 0.06 | M16: 0.055 | N16: 0.05 | O16: 0.046 | P16: 0.042 | Q16: 0.038 | R16: 0.035 | S16: Segment growth per the FY2025 annual report's outlook statement — FY2016-FY2025 annual reports, segment note
A17: Other markets | L17: 0.03 | M17: 0.028 | N17: 0.026 | O17: 0.024 | P17: 0.022 | Q17: 0.02 | R17: 0.018 | S17: Segment growth per the FY2025 annual report's outlook statement — FY2016-FY2025 annual reports, segment note
A19: Share of revenue
A20: Domestic | B20: =B4/B8 | C20: =C4/C8 | D20: =D4/D8 | E20: =E4/E8 | F20: =F4/F8 | G20: =G4/G8 | H20: =H4/H8 | I20: =I4/I8 | ... R20: =R4/R8
A21: North America | B21: =B5/B8 | C21: =C5/C8 | D21: =D5/D8 | E21: =E5/E8 | F21: =F5/F8 | G21: =G5/G8 | H21: =H5/H8 | I21: =I5/I8 | ... R21: =R5/R8
A22: Europe | B22: =B6/B8 | C22: =C6/C8 | D22: =D6/D8 | E22: =E6/E8 | F22: =F6/F8 | G22: =G6/G8 | H22: =H6/H8 | I22: =I6/I8 | ... R22: =R6/R8
A23: Other markets | B23: =B7/B8 | C23: =C7/C8 | D23: =D7/D8 | E23: =E7/E8 | F23: =F7/F8 | G23: =G7/G8 | H23: =H7/H8 | I23: =I7/I8 | ... R23: =R7/R8

Sheet BETA_REGRESSION
A1: BETA REGRESSION — stock returns on index returns
A2: Blue columns are the price series. The beta is the slope of the fit, and R² says how much of the share's movement the index actually explains.
A3: Date | B3: Stock price | C3: Stock return | D3: Index price | E3: Index return | G3: Regression output
B4: 928 | D4: 18500 | G4: Observations | H4: =COUNT(C5:C123) | I4: 120 weekly closes to 2026-10-16, regressed on the local index
B5: 935.13 | C5: =B5/B4-1 | D5: 18450.76 | E5: =D5/D4-1 | G5: Slope (raw beta) | H5: =SLOPE(C5:C123,E5:E123)
B6: 926.69 | C6: =B6/B5-1 | D6: 18412.09 | E6: =D6/D5-1 | G6: Intercept (alpha) | H6: =INTERCEPT(C5:C123,E5:E123)
B7: 906.05 | C7: =B7/B6-1 | D7: 18127.25 | E7: =D7/D6-1 | G7: R² | H7: =RSQ(C5:C123,E5:E123) | I7: A low R² is a reason to lean on the peer-derived beta instead of this one
B8: 938.42 | C8: =B8/B7-1 | D8: 18550.09 | E8: =D8/D7-1 | G8: Frequency | H8: weekly
B9: 966.96 | C9: =B9/B8-1 | D9: 18956.35 | E9: =D9/D8-1
B10: 981.51 | C10: =B10/B9-1 | D10: 19140.24 | E10: =D10/D9-1
B11: 965.89 | C11: =B11/B10-1 | D11: 18576.46 | E11: =D11/D10-1
B12: 989.14 | C12: =B12/B11-1 | D12: 18796.06 | E12: =D12/D11-1
B13: 918.87 | C13: =B13/B12-1 | D13: 18233.38 | E13: =D13/D12-1
B14: 894.3 | C14: =B14/B13-1 | D14: 17965.3 | E14: =D14/D13-1
B15: 901.66 | C15: =B15/B14-1 | D15: 18109.09 | E15: =D15/D14-1
B16: 902.05 | C16: =B16/B15-1 | D16: 18328.18 | E16: =D16/D15-1
B17: 917.88 | C17: =B17/B16-1 | D17: 18476 | E17: =D17/D16-1
B18: 940.05 | C18: =B18/B17-1 | D18: 18284.56 | E18: =D18/D17-1
B19: 977.49 | C19: =B19/B18-1 | D19: 18518.16 | E19: =D19/D18-1
B20: 951.54 | C20: =B20/B19-1 | D20: 18340.64 | E20: =D20/D19-1
... B123: 1479.9 | C123: =B123/B122-1 | D123: 28153.55 | E123: =D123/D122-1

Sheet WACC
A1: WACC — derived, not asserted
A2: Beta from a peer set and a regression; the equity risk premium from a market return history; the cost of debt from interest actually paid. Blue cells are the sourced inputs.
A4: Peer | B4: Total debt | C4: Total equity | D4: Tax rate | E4: D/E | F4: D/(D+E) | G4: Levered beta | H4: Unlevered beta | I4: Source
A5: Peer One | B5: 1800 | C5: 9200 | D5: 0.25 | E5: =B5/C5 | F5: =B5/(B5+C5) | G5: 0.684 | H5: =G5/(1+(1-D5)*E5) | I5: exchange data and FY2025 accounts, 2026-10-16
A6: Peer Two | B6: 900 | C6: 14500 | D6: 0.25 | E6: =B6/C6 | F6: =B6/(B6+C6) | G6: 0.33 | H6: =G6/(1+(1-D6)*E6) | I6: exchange data and FY2025 accounts, 2026-10-16
A7: Peer Three | B7: 3100 | C7: 8700 | D7: 0.25 | E7: =B7/C7 | F7: =B7/(B7+C7) | G7: 0.788 | H7: =G7/(1+(1-D7)*E7) | I7: exchange data and FY2025 accounts, 2026-10-16
A8: Peer Four | B8: 2200 | C8: 10100 | D8: 0.25 | E8: =B8/C8 | F8: =B8/(B8+C8) | G8: 0.673 | H8: =G8/(1+(1-D8)*E8) | I8: exchange data and FY2025 accounts, 2026-10-16
A9: Peer Five | B9: 1500 | C9: 7300 | D9: 0.25 | E9: =B9/C9 | F9: =B9/(B9+C9) | G9: 0.658 | H9: =G9/(1+(1-D9)*E9) | I9: exchange data and FY2025 accounts, 2026-10-16
A10: Median | E10: =MEDIAN(E5:E9) | F10: =MEDIAN(F5:F9) | G10: =MEDIAN(G5:G9) | H10: =MEDIAN(H5:H9) | I10: Unlevering strips each peer's financing out of its observed beta, leaving business risk only (Hamada)
A12: Regression beta, Blume-adjusted
A13: Raw regression beta | B13: =BETA_REGRESSION!H5 | C13: 120 weekly closes to 2026-10-16, regressed on the local index
A14: Weight on the raw beta | B14: 0.75
A15: Market beta (shrink target) | B15: 1
A16: Adjusted beta | B16: =B13*B14+B15*(1-B14) | C16: Blume: betas drift toward 1 over time, so the raw estimate is shrunk toward the market
A17: R² of the regression | B17: =BETA_REGRESSION!H7 | C17: How much of the share's movement the index explains. A low figure is a reason to lean on the peer-derived beta instead
A19: Beta used in the cost of equity
A20: Target debt / equity | B20: 0.35
A21: Peer beta re-levered at the target structure | B21: =H10*(1+(1-B63)*B20)
A22: Beta source (1 comps, 2 regression, 3 average) | B22: 3
A23: Beta used | B23: =CHOOSE(B22,B21,B16,AVERAGE(B21,B16))
A25: Equity risk premium from the market record
A26: Year | B26: Market return
A27: 2001 | B27: -0.13
A28: 2002 | B28: -0.234
A29: 2003 | B29: 0.264
A30: 2004 | B30: 0.09
A31: 2005 | B31: 0.03
A32: 2006 | B32: 0.136
A33: 2007 | B33: 0.035
A34: 2008 | B34: -0.385
A35: 2009 | B35: 0.235
A36: 2010 | B36: 0.128
A37: 2011 | B37: 0
A38: 2012 | B38: 0.134
... A51: 2025 | B51: 0.085
A53: Average annual price return (25 years) | B53: =AVERAGE(B27:B51) | C53: Index annual total price returns 2001-2025; dividend yield from the index factsheet, 2026-10-16
A54: Dividend yield | B54: 0.016
A55: Total market return | B55: =B53+B54
A56: Risk-free rate | B56: 0.042
A57: Equity risk premium | B57: =B55-B56 | C57: A premium derived from a long record rather than a round number; the window length is itself an assumption
...

Sheet PROJECTION
A1: PROJECTION — every cell a formula off INPUTS
A2: Nothing here is typed in. Change an assumption on INPUTS and watch this move.
A3: Metric | B3: 2026 | C3: 2027 | D3: 2028 | E3: 2029 | F3: 2030 | G3: 2031 | H3: 2032
A4: Revenue | B4: =HISTORICALS!$K$4*(1+INPUTS!B$22) | C4: =B4*(1+INPUTS!C$22) | D4: =C4*(1+INPUTS!D$22) | E4: =D4*(1+INPUTS!E$22) | F4: =E4*(1+INPUTS!F$22) | G4: =F4*(1+INPUTS!G$22) | H4: =G4*(1+INPUTS!H$22)
A5: EBIT | B5: =B4*INPUTS!B$23 | C5: =C4*INPUTS!C$23 | D5: =D4*INPUTS!D$23 | E5: =E4*INPUTS!E$23 | F5: =F4*INPUTS!F$23 | G5: =G4*INPUTS!G$23 | H5: =H4*INPUTS!H$23
A6: Tax on EBIT | B6: =B5*INPUTS!$B$4 | C6: =C5*INPUTS!$B$4 | D6: =D5*INPUTS!$B$4 | E6: =E5*INPUTS!$B$4 | F6: =F5*INPUTS!$B$4 | G6: =G5*INPUTS!$B$4 | H6: =H5*INPUTS!$B$4
A7: NOPAT | B7: =B5-B6 | C7: =C5-C6 | D7: =D5-D6 | E7: =E5-E6 | F7: =F5-F6 | G7: =G5-G6 | H7: =H5-H6
A8: D&A | B8: =B4*INPUTS!B$24 | C8: =C4*INPUTS!C$24 | D8: =D4*INPUTS!D$24 | E8: =E4*INPUTS!E$24 | F8: =F4*INPUTS!F$24 | G8: =G4*INPUTS!G$24 | H8: =H4*INPUTS!H$24
A9: Capex | B9: =B4*INPUTS!B$25 | C9: =C4*INPUTS!C$25 | D9: =D4*INPUTS!D$25 | E9: =E4*INPUTS!E$25 | F9: =F4*INPUTS!F$25 | G9: =G4*INPUTS!G$25 | H9: =H4*INPUTS!H$25
A10: Net working capital (balance) | B10: =B4*INPUTS!B$26 | C10: =C4*INPUTS!C$26 | D10: =D4*INPUTS!D$26 | E10: =E4*INPUTS!E$26 | F10: =F4*INPUTS!F$26 | G10: =G4*INPUTS!G$26 | H10: =H4*INPUTS!H$26
A11: Change in net working capital | B11: =B10-HISTORICALS!$K$9 | C11: =C10-B10 | D11: =D10-C10 | E11: =E10-D10 | F11: =F10-E10 | G11: =G10-F10 | H11: =H10-G10
A12: Unlevered free cash flow | B12: =B7+B8-B9-B11 | C12: =C7+C8-C9-C11 | D12: =D7+D8-D9-D11 | E12: =E7+E8-E9-E11 | F12: =F7+F8-F9-F11 | G12: =G7+G8-G9-G11 | H12: =H7+H8-H9-H11

Sheet VALUATION
A1: VALUATION — DCF with an exit-multiple and comparables cross-check
A2: Outputs a value range under stated assumptions. It does not say whether to buy or sell.
A3: Metric | B3: Y1 | C3: Y2 | D3: Y3 | E3: Y4 | F3: Y5 | G3: Y6 | H3: Y7
A4: Unlevered free cash flow | B4: =PROJECTION!B12 | C4: =PROJECTION!C12 | D4: =PROJECTION!D12 | E4: =PROJECTION!E12 | F4: =PROJECTION!F12 | G4: =PROJECTION!G12 | H4: =PROJECTION!H12
A5: Discount period | B5: =INPUTS!$B$18+COLUMN(B5)-2 | C5: =INPUTS!$B$18+COLUMN(C5)-2 | D5: =INPUTS!$B$18+COLUMN(D5)-2 | E5: =INPUTS!$B$18+COLUMN(E5)-2 | F5: =INPUTS!$B$18+COLUMN(F5)-2 | G5: =INPUTS!$B$18+COLUMN(G5)-2 | H5: =INPUTS!$B$18+COLUMN(H5)-2
A6: Discount factor | B6: =1/(1+INPUTS!$B$10)^B5 | C6: =1/(1+INPUTS!$B$10)^C5 | D6: =1/(1+INPUTS!$B$10)^D5 | E6: =1/(1+INPUTS!$B$10)^E5 | F6: =1/(1+INPUTS!$B$10)^F5 | G6: =1/(1+INPUTS!$B$10)^G5 | H6: =1/(1+INPUTS!$B$10)^H5
A7: PV of free cash flow | B7: =B4*B6 | C7: =C4*C6 | D7: =D4*D6 | E7: =E4*E6 | F7: =F4*F6 | G7: =G4*G6 | H7: =H4*H6
A9: PV of explicit-period FCF | B9: =SUM(B7:H7)
A10: Terminal value (perpetuity growth) | B10: =H4*(1+INPUTS!$B$11)/(INPUTS!$B$10-INPUTS!$B$11)
A11: PV of terminal value | B11: =B10*H6
A12: Enterprise value | B12: =B9+B11
A13: Less: net debt | B13: =INPUTS!$B$13
A14: Equity value | B14: =B12-B13
A15: Shares outstanding | B15: =INPUTS!$B$14
A16: Value per share (DCF, perpetuity) | B16: =B14/B15
A17: Current share price | B17: =INPUTS!$B$15
A18: Model value vs current price (arithmetic only) | B18: =B16/B17-1
A20: Cross-check 1 — exit multiple terminal value
A21: Terminal-year EBITDA | B21: =PROJECTION!H5+PROJECTION!H8
A22: Terminal value (exit multiple) | B22: =B21*INPUTS!$B$12
A23: PV of terminal value (exit) | B23: =B22*H6
A24: Enterprise value (exit method) | B24: =B9+B23
A25: Value per share (exit method) | B25: =(B24-INPUTS!$B$13)/INPUTS!$B$14
A27: Cross-check 2 — comparables
A28: Peer median EV/EBITDA | B28: =MEDIAN(INPUTS!B30:B32)
A29: Y1 EBITDA | B29: =PROJECTION!B5+PROJECTION!B8
A30: Implied enterprise value (comps) | B30: =B28*B29
A31: Implied value per share (comps) | B31: =(B30-INPUTS!$B$13)/INPUTS!$B$14

Sheet INTRINSIC_GROWTH
A1: INTRINSIC GROWTH — what the business can fund
A2: g = reinvestment rate × ROIC. Not a forecast — a benchmark to judge the forecast against.
A3: Metric | B3: 2016 | C3: 2017 | D3: 2018 | E3: 2019 | F3: 2020 | G3: 2021 | H3: 2022 | I3: 2023 | J3: 2024 | K3: 2025
A4: Net PP&E | B4: =HISTORICALS!B12 | C4: =HISTORICALS!C12 | D4: =HISTORICALS!D12 | E4: =HISTORICALS!E12 | F4: =HISTORICALS!F12 | G4: =HISTORICALS!G12 | H4: =HISTORICALS!H12 | I4: =HISTORICALS!I12 | ... K4: =HISTORICALS!K12
A5: Net working capital | B5: =HISTORICALS!B9 | C5: =HISTORICALS!C9 | D5: =HISTORICALS!D9 | E5: =HISTORICALS!E9 | F5: =HISTORICALS!F9 | G5: =HISTORICALS!G9 | H5: =HISTORICALS!H9 | I5: =HISTORICALS!I9 | ... K5: =HISTORICALS!K9
A6: Invested capital | B6: =B4+B5 | C6: =C4+C5 | D6: =D4+D5 | E6: =E4+E5 | F6: =F4+F5 | G6: =G4+G5 | H6: =H4+H5 | I6: =I4+I5 | ... K6: =K4+K5
A7: EBIT | B7: =HISTORICALS!B5 | C7: =HISTORICALS!C5 | D7: =HISTORICALS!D5 | E7: =HISTORICALS!E5 | F7: =HISTORICALS!F5 | G7: =HISTORICALS!G5 | H7: =HISTORICALS!H5 | I7: =HISTORICALS!I5 | ... K7: =HISTORICALS!K5
A8: NOPAT | B8: =B7*(1-WACC!$B$63) | C8: =C7*(1-WACC!$B$63) | D8: =D7*(1-WACC!$B$63) | E8: =E7*(1-WACC!$B$63) | F8: =F7*(1-WACC!$B$63) | G8: =G7*(1-WACC!$B$63) | H8: =H7*(1-WACC!$B$63) | I8: =I7*(1-WACC!$B$63) | ... K8: =K7*(1-WACC!$B$63)
A9: ROIC | B9: =B8/B6 | C9: =C8/C6 | D9: =D8/D6 | E9: =E8/E6 | F9: =F8/F6 | G9: =G8/G6 | H9: =H8/H6 | I9: =I8/I6 | ... K9: =K8/K6
A11: Reinvestment rate (latest year)
A12: Net capex (capex less D&A) | B12: =HISTORICALS!K8-HISTORICALS!K7
A13: Change in working capital | B13: =K5-J5
A14: Reinvestment | B14: =B12+B13
A15: NOPAT | B15: =K8
A16: Reinvestment rate | B16: =B14/B15
A18: Growth the company can fund
A19: ROIC (latest) | B19: =K9
A20: Intrinsic growth (RR × ROIC) | B20: =B16*B19
A21: Year-1 revenue growth assumed on INPUTS | B21: =INPUTS!B20
A22: Terminal growth assumed on INPUTS | B22: =INPUTS!$B$11 | C22: Terminal growth above intrinsic growth assumes the company improves forever — the strongest claim in any DCF
A23: Assumed growth vs what the company can fund | B23: =IF(B21<=B20,"Within intrinsic growth","Above intrinsic growth — needs margin expansion, better capital efficiency, or a stated reason") | C23: Growing faster than RR × ROIC means funding growth from somewhere the record does not show. That is allowed; it is not free

Sheet RELATIVE_PRICING
A1: RELATIVE PRICING — the whole peer distribution
A2: A median alone hides the spread. The quartiles are what the football field is built from.
A5: Peer | B5: Share price | C5: Shares | D5: Equity value | E5: Total debt | F5: Cash | G5: Net debt | H5: Enterprise value | I5: Revenue | J5: EBITDA | K5: Net income | L5: EV/Revenue | M5: EV/EBITDA | N5: P/E | O5: Source
A6: Peer One | B6: 93.38 | C6: 260 | D6: =B6*C6 | E6: 1800 | F6: 600 | G6: =E6-F6 | H6: =D6+G6 | I6: 9800 | J6: 2450 | K6: 1380 | L6: =H6/I6 | M6: =H6/J6 | N6: =D6/K6 | O6: exchange data and FY2025 accounts, 2026-10-16
A7: Peer Two | B7: 209.21 | C7: 240 | D7: =B7*C7 | E7: 900 | F7: 1500 | G7: =E7-F7 | H7: =D7+G7 | I7: 14200 | J7: 4100 | K7: 2560 | L7: =H7/I7 | M7: =H7/J7 | N7: =D7/K7 | O7: exchange data and FY2025 accounts, 2026-10-16
A8: Peer Three | B8: 44.18 | C8: 310 | D8: =B8*C8 | E8: 3100 | F8: 420 | G8: =E8-F8 | H8: =D8+G8 | I8: 8100 | J8: 1780 | K8: 860 | L8: =H8/I8 | M8: =H8/J8 | N8: =D8/K8 | O8: exchange data and FY2025 accounts, 2026-10-16
A9: Peer Four | B9: 112.64 | C9: 180 | D9: =B9*C9 | E9: 2200 | F9: 780 | G9: =E9-F9 | H9: =D9+G9 | I9: 7400 | J9: 1920 | K9: 1010 | L9: =H9/I9 | M9: =H9/J9 | N9: =D9/K9 | O9: exchange data and FY2025 accounts, 2026-10-16
A10: Peer Five | B10: 27.29 | C10: 390 | D10: =B10*C10 | E10: 1500 | F10: 350 | G10: =E10-F10 | H10: =D10+G10 | I10: 6200 | J10: 1340 | K10: 640 | L10: =H10/I10 | M10: =H10/J10 | N10: =D10/K10 | O10: exchange data and FY2025 accounts, 2026-10-16
A11: Peer Six | B11: 168.25 | C11: 120 | D11: =B11*C11 | E11: 600 | F11: 900 | G11: =E11-F11 | H11: =D11+G11 | I11: 5100 | J11: 1530 | K11: 980 | L11: =H11/I11 | M11: =H11/J11 | N11: =D11/K11 | O11: exchange data and FY2025 accounts, 2026-10-16
A13: High | L13: =MAX(L6:L11) | M13: =MAX(M6:M11) | N13: =MAX(N6:N11)
A14: 75th percentile | L14: =SMALL(L6:L11,5)+0.25*(SMALL(L6:L11,6)-SMALL(L6:L11,5)) | M14: =SMALL(M6:M11,5)+0.25*(SMALL(M6:M11,6)-SMALL(M6:M11,5)) | N14: =SMALL(N6:N11,5)+0.25*(SMALL(N6:N11,6)-SMALL(N6:N11,5))
A15: Average | L15: =AVERAGE(L6:L11) | M15: =AVERAGE(M6:M11) | N15: =AVERAGE(N6:N11)
A16: Median | L16: =MEDIAN(L6:L11) | M16: =MEDIAN(M6:M11) | N16: =MEDIAN(N6:N11)
A17: 25th percentile | L17: =SMALL(L6:L11,1)+0.75*(SMALL(L6:L11,2)-SMALL(L6:L11,1)) | M17: =SMALL(M6:M11,1)+0.75*(SMALL(M6:M11,2)-SMALL(M6:M11,1)) | N17: =SMALL(N6:N11,1)+0.75*(SMALL(N6:N11,2)-SMALL(N6:N11,1))
A18: Low | L18: =MIN(L6:L11) | M18: =MIN(M6:M11) | N18: =MIN(N6:N11)
A20: The subject company
A21: Revenue (NTM) | B21: 4601 | C21: On the same basis as the peers above — forward figures against forward multiples, or the comparison is meaningless
A22: EBITDA (NTM) | B22: 1205.5
A23: Net income (NTM) | B23: 690.2
A24: Net debt | B24: 1150
A25: Shares outstanding | B25: 420
A27: Implied value per share | L27: EV/Revenue | M27: EV/EBITDA | N27: P/E
A28: At the 25th percentile | L28: =(L17*B21-B24)/B25 | M28: =(M17*B22-B24)/B25 | N28: =N17*B23/B25
A29: At the median | L29: =(L16*B21-B24)/B25 | M29: =(M16*B22-B24)/B25 | N29: =N16*B23/B25
A30: At the 75th percentile | L30: =(L14*B21-B24)/B25 | M30: =(M14*B22-B24)/B25 | N30: =N14*B23/B25 | O30: P/E needs no net debt adjustment — earnings are already after interest

Sheet SENSITIVITY
A1: SENSITIVITY — value per share: WACC vs Terminal growth rate
A2: Axis values are driven off INPUTS by the step cells (B16/B17). Change a step and the grid re-spaces itself.
B3: WACC ↓ / Terminal growth rate →
C4: =INPUTS!$B$11+(COLUMN(C4)-5)*INPUTS!$B$17 | D4: =INPUTS!$B$11+(COLUMN(D4)-5)*INPUTS!$B$17 | E4: =INPUTS!$B$11+(COLUMN(E4)-5)*INPUTS!$B$17 | F4: =INPUTS!$B$11+(COLUMN(F4)-5)*INPUTS!$B$17 | G4: =INPUTS!$B$11+(COLUMN(G4)-5)*INPUTS!$B$17
B5: =INPUTS!$B$10+(ROW(B5)-7)*INPUTS!$B$16 | C5: =IF($B5<=C$4,NA(),(SUMPRODUCT($B24:$H24,1/(1+$B5)^VALUATION!$B$5:$H$5)+$H24*(1+C$4)/($B5-C$4)/(1+$B5)^VALUATION!$H$5-INPUTS!$B$13)/INPUTS!$B$14) | D5: =IF($B5<=D$4,NA(),(SUMPRODUCT($B37:$H37,1/(1+$B5)^VALUATION!$B$5:$H$5)+$H37*(1+D$4)/($B5-D$4)/(1+$B5)^VALUATION!$H$5-INPUTS!$B$13)/INPUTS!$B$14) | E5: =IF($B5<=E$4,NA(),(SUMPRODUCT($B50:$H50,1/(1+$B5)^VALUATION!$B$5:$H$5)+$H50*(1+E$4)/($B5-E$4)/(1+$B5)^VALUATION!$H$5-INPUTS!$B$13)/INPUTS!$B$14) | F5: =IF($B5<=F$4,NA(),(SUMPRODUCT($B63:$H63,1/(1+$B5)^VALUATION!$B$5:$H$5)+$H63*(1+F$4)/($B5-F$4)/(1+$B5)^VALUATION!$H$5-INPUTS!$B$13)/INPUTS!$B$14) | G5: =IF($B5<=G$4,NA(),(SUMPRODUCT($B76:$H76,1/(1+$B5)^VALUATION!$B$5:$H$5)+$H76*(1+G$4)/($B5-G$4)/(1+$B5)^VALUATION!$H$5-INPUTS!$B$13)/INPUTS!$B$14)
B6: =INPUTS!$B$10+(ROW(B6)-7)*INPUTS!$B$16 | C6: =IF($B6<=C$4,NA(),(SUMPRODUCT($B24:$H24,1/(1+$B6)^VALUATION!$B$5:$H$5)+$H24*(1+C$4)/($B6-C$4)/(1+$B6)^VALUATION!$H$5-INPUTS!$B$13)/INPUTS!$B$14) | D6: =IF($B6<=D$4,NA(),(SUMPRODUCT($B37:$H37,1/(1+$B6)^VALUATION!$B$5:$H$5)+$H37*(1+D$4)/($B6-D$4)/(1+$B6)^VALUATION!$H$5-INPUTS!$B$13)/INPUTS!$B$14) | E6: =IF($B6<=E$4,NA(),(SUMPRODUCT($B50:$H50,1/(1+$B6)^VALUATION!$B$5:$H$5)+$H50*(1+E$4)/($B6-E$4)/(1+$B6)^VALUATION!$H$5-INPUTS!$B$13)/INPUTS!$B$14) | F6: =IF($B6<=F$4,NA(),(SUMPRODUCT($B63:$H63,1/(1+$B6)^VALUATION!$B$5:$H$5)+$H63*(1+F$4)/($B6-F$4)/(1+$B6)^VALUATION!$H$5-INPUTS!$B$13)/INPUTS!$B$14) | G6: =IF($B6<=G$4,NA(),(SUMPRODUCT($B76:$H76,1/(1+$B6)^VALUATION!$B$5:$H$5)+$H76*(1+G$4)/($B6-G$4)/(1+$B6)^VALUATION!$H$5-INPUTS!$B$13)/INPUTS!$B$14)
B7: =INPUTS!$B$10+(ROW(B7)-7)*INPUTS!$B$16 | C7: =IF($B7<=C$4,NA(),(SUMPRODUCT($B24:$H24,1/(1+$B7)^VALUATION!$B$5:$H$5)+$H24*(1+C$4)/($B7-C$4)/(1+$B7)^VALUATION!$H$5-INPUTS!$B$13)/INPUTS!$B$14) | D7: =IF($B7<=D$4,NA(),(SUMPRODUCT($B37:$H37,1/(1+$B7)^VALUATION!$B$5:$H$5)+$H37*(1+D$4)/($B7-D$4)/(1+$B7)^VALUATION!$H$5-INPUTS!$B$13)/INPUTS!$B$14) | E7: =IF($B7<=E$4,NA(),(SUMPRODUCT($B50:$H50,1/(1+$B7)^VALUATION!$B$5:$H$5)+$H50*(1+E$4)/($B7-E$4)/(1+$B7)^VALUATION!$H$5-INPUTS!$B$13)/INPUTS!$B$14) | F7: =IF($B7<=F$4,NA(),(SUMPRODUCT($B63:$H63,1/(1+$B7)^VALUATION!$B$5:$H$5)+$H63*(1+F$4)/($B7-F$4)/(1+$B7)^VALUATION!$H$5-INPUTS!$B$13)/INPUTS!$B$14) | G7: =IF($B7<=G$4,NA(),(SUMPRODUCT($B76:$H76,1/(1+$B7)^VALUATION!$B$5:$H$5)+$H76*(1+G$4)/($B7-G$4)/(1+$B7)^VALUATION!$H$5-INPUTS!$B$13)/INPUTS!$B$14)
B8: =INPUTS!$B$10+(ROW(B8)-7)*INPUTS!$B$16 | C8: =IF($B8<=C$4,NA(),(SUMPRODUCT($B24:$H24,1/(1+$B8)^VALUATION!$B$5:$H$5)+$H24*(1+C$4)/($B8-C$4)/(1+$B8)^VALUATION!$H$5-INPUTS!$B$13)/INPUTS!$B$14) | D8: =IF($B8<=D$4,NA(),(SUMPRODUCT($B37:$H37,1/(1+$B8)^VALUATION!$B$5:$H$5)+$H37*(1+D$4)/($B8-D$4)/(1+$B8)^VALUATION!$H$5-INPUTS!$B$13)/INPUTS!$B$14) | E8: =IF($B8<=E$4,NA(),(SUMPRODUCT($B50:$H50,1/(1+$B8)^VALUATION!$B$5:$H$5)+$H50*(1+E$4)/($B8-E$4)/(1+$B8)^VALUATION!$H$5-INPUTS!$B$13)/INPUTS!$B$14) | F8: =IF($B8<=F$4,NA(),(SUMPRODUCT($B63:$H63,1/(1+$B8)^VALUATION!$B$5:$H$5)+$H63*(1+F$4)/($B8-F$4)/(1+$B8)^VALUATION!$H$5-INPUTS!$B$13)/INPUTS!$B$14) | G8: =IF($B8<=G$4,NA(),(SUMPRODUCT($B76:$H76,1/(1+$B8)^VALUATION!$B$5:$H$5)+$H76*(1+G$4)/($B8-G$4)/(1+$B8)^VALUATION!$H$5-INPUTS!$B$13)/INPUTS!$B$14)
B9: =INPUTS!$B$10+(ROW(B9)-7)*INPUTS!$B$16 | C9: =IF($B9<=C$4,NA(),(SUMPRODUCT($B24:$H24,1/(1+$B9)^VALUATION!$B$5:$H$5)+$H24*(1+C$4)/($B9-C$4)/(1+$B9)^VALUATION!$H$5-INPUTS!$B$13)/INPUTS!$B$14) | D9: =IF($B9<=D$4,NA(),(SUMPRODUCT($B37:$H37,1/(1+$B9)^VALUATION!$B$5:$H$5)+$H37*(1+D$4)/($B9-D$4)/(1+$B9)^VALUATION!$H$5-INPUTS!$B$13)/INPUTS!$B$14) | E9: =IF($B9<=E$4,NA(),(SUMPRODUCT($B50:$H50,1/(1+$B9)^VALUATION!$B$5:$H$5)+$H50*(1+E$4)/($B9-E$4)/(1+$B9)^VALUATION!$H$5-INPUTS!$B$13)/INPUTS!$B$14) | F9: =IF($B9<=F$4,NA(),(SUMPRODUCT($B63:$H63,1/(1+$B9)^VALUATION!$B$5:$H$5)+$H63*(1+F$4)/($B9-F$4)/(1+$B9)^VALUATION!$H$5-INPUTS!$B$13)/INPUTS!$B$14) | G9: =IF($B9<=G$4,NA(),(SUMPRODUCT($B76:$H76,1/(1+$B9)^VALUATION!$B$5:$H$5)+$H76*(1+G$4)/($B9-G$4)/(1+$B9)^VALUATION!$H$5-INPUTS!$B$13)/INPUTS!$B$14)
B11: Shaded centre cell = base case; it must equal VALUATION value per share (CHECKS verifies this).
A14: Helper blocks — one formula-driven projection per grid column (that column's shift applied to the INPUTS driver).
A16: Column 1: Terminal growth rate = | B16: =C$4
A17: Revenue | B17: =HISTORICALS!$K$4*(1+INPUTS!B$22) | C17: =B17*(1+INPUTS!C$22) | D17: =C17*(1+INPUTS!D$22) | E17: =D17*(1+INPUTS!E$22) | F17: =E17*(1+INPUTS!F$22) | G17: =F17*(1+INPUTS!G$22) | H17: =G17*(1+INPUTS!H$22)
A18: EBIT | B18: =B17*(INPUTS!B$23) | C18: =C17*(INPUTS!C$23) | D18: =D17*(INPUTS!D$23) | E18: =E17*(INPUTS!E$23) | F18: =F17*(INPUTS!F$23) | G18: =G17*(INPUTS!G$23) | H18: =H17*(INPUTS!H$23)
A19: NOPAT | B19: =B18*(1-INPUTS!$B$4) | C19: =C18*(1-INPUTS!$B$4) | D19: =D18*(1-INPUTS!$B$4) | E19: =E18*(1-INPUTS!$B$4) | F19: =F18*(1-INPUTS!$B$4) | G19: =G18*(1-INPUTS!$B$4) | H19: =H18*(1-INPUTS!$B$4)
A20: D&A | B20: =B17*INPUTS!B$24 | C20: =C17*INPUTS!C$24 | D20: =D17*INPUTS!D$24 | E20: =E17*INPUTS!E$24 | F20: =F17*INPUTS!F$24 | G20: =G17*INPUTS!G$24 | H20: =H17*INPUTS!H$24
A21: Capex | B21: =B17*INPUTS!B$25 | C21: =C17*INPUTS!C$25 | D21: =D17*INPUTS!D$25 | E21: =E17*INPUTS!E$25 | F21: =F17*INPUTS!F$25 | G21: =G17*INPUTS!G$25 | H21: =H17*INPUTS!H$25
A22: NWC balance | B22: =B17*INPUTS!B$26 | C22: =C17*INPUTS!C$26 | D22: =D17*INPUTS!D$26 | E22: =E17*INPUTS!E$26 | F22: =F17*INPUTS!F$26 | G22: =G17*INPUTS!G$26 | H22: =H17*INPUTS!H$26
A23: Change in NWC | B23: =B22-HISTORICALS!$K$9 | C23: =C22-B22 | D23: =D22-C22 | E23: =E22-D22 | F23: =F22-E22 | G23: =G22-F22 | H23: =H22-G22
A24: Unlevered FCF | B24: =B19+B20-B21-B23 | C24: =C19+C20-C21-C23 | D24: =D19+D20-D21-D23 | E24: =E19+E20-E21-E23 | F24: =F19+F20-F21-F23 | G24: =G19+G20-G21-G23 | H24: =H19+H20-H21-H23
A29: Column 2: Terminal growth rate = | B29: =D$4
A30: Revenue | B30: =HISTORICALS!$K$4*(1+INPUTS!B$22) | C30: =B30*(1+INPUTS!C$22) | D30: =C30*(1+INPUTS!D$22) | E30: =D30*(1+INPUTS!E$22) | F30: =E30*(1+INPUTS!F$22) | G30: =F30*(1+INPUTS!G$22) | H30: =G30*(1+INPUTS!H$22)
A31: EBIT | B31: =B30*(INPUTS!B$23) | C31: =C30*(INPUTS!C$23) | D31: =D30*(INPUTS!D$23) | E31: =E30*(INPUTS!E$23) | F31: =F30*(INPUTS!F$23) | G31: =G30*(INPUTS!G$23) | H31: =H30*(INPUTS!H$23)
A32: NOPAT | B32: =B31*(1-INPUTS!$B$4) | C32: =C31*(1-INPUTS!$B$4) | D32: =D31*(1-INPUTS!$B$4) | E32: =E31*(1-INPUTS!$B$4) | F32: =F31*(1-INPUTS!$B$4) | G32: =G31*(1-INPUTS!$B$4) | H32: =H31*(1-INPUTS!$B$4)
A33: D&A | B33: =B30*INPUTS!B$24 | C33: =C30*INPUTS!C$24 | D33: =D30*INPUTS!D$24 | E33: =E30*INPUTS!E$24 | F33: =F30*INPUTS!F$24 | G33: =G30*INPUTS!G$24 | H33: =H30*INPUTS!H$24
A34: Capex | B34: =B30*INPUTS!B$25 | C34: =C30*INPUTS!C$25 | D34: =D30*INPUTS!D$25 | E34: =E30*INPUTS!E$25 | F34: =F30*INPUTS!F$25 | G34: =G30*INPUTS!G$25 | H34: =H30*INPUTS!H$25
A35: NWC balance | B35: =B30*INPUTS!B$26 | C35: =C30*INPUTS!C$26 | D35: =D30*INPUTS!D$26 | E35: =E30*INPUTS!E$26 | F35: =F30*INPUTS!F$26 | G35: =G30*INPUTS!G$26 | H35: =H30*INPUTS!H$26
A36: Change in NWC | B36: =B35-HISTORICALS!$K$9 | C36: =C35-B35 | D36: =D35-C35 | E36: =E35-D35 | F36: =F35-E35 | G36: =G35-F35 | H36: =H35-G35
A37: Unlevered FCF | B37: =B32+B33-B34-B36 | C37: =C32+C33-C34-C36 | D37: =D32+D33-D34-D36 | E37: =E32+E33-E34-E36 | F37: =F32+F33-F34-F36 | G37: =G32+G33-G34-G36 | H37: =H32+H33-H34-H36
A42: Column 3: Terminal growth rate = | B42: =E$4
A43: Revenue | B43: =HISTORICALS!$K$4*(1+INPUTS!B$22) | C43: =B43*(1+INPUTS!C$22) | D43: =C43*(1+INPUTS!D$22) | E43: =D43*(1+INPUTS!E$22) | F43: =E43*(1+INPUTS!F$22) | G43: =F43*(1+INPUTS!G$22) | H43: =G43*(1+INPUTS!H$22)
A44: EBIT | B44: =B43*(INPUTS!B$23) | C44: =C43*(INPUTS!C$23) | D44: =D43*(INPUTS!D$23) | E44: =E43*(INPUTS!E$23) | F44: =F43*(INPUTS!F$23) | G44: =G43*(INPUTS!G$23) | H44: =H43*(INPUTS!H$23)
A45: NOPAT | B45: =B44*(1-INPUTS!$B$4) | C45: =C44*(1-INPUTS!$B$4) | D45: =D44*(1-INPUTS!$B$4) | E45: =E44*(1-INPUTS!$B$4) | F45: =F44*(1-INPUTS!$B$4) | G45: =G44*(1-INPUTS!$B$4) | H45: =H44*(1-INPUTS!$B$4)
A46: D&A | B46: =B43*INPUTS!B$24 | C46: =C43*INPUTS!C$24 | D46: =D43*INPUTS!D$24 | E46: =E43*INPUTS!E$24 | F46: =F43*INPUTS!F$24 | G46: =G43*INPUTS!G$24 | H46: =H43*INPUTS!H$24
A47: Capex | B47: =B43*INPUTS!B$25 | C47: =C43*INPUTS!C$25 | D47: =D43*INPUTS!D$25 | E47: =E43*INPUTS!E$25 | F47: =F43*INPUTS!F$25 | G47: =G43*INPUTS!G$25 | H47: =H43*INPUTS!H$25
A48: NWC balance | B48: =B43*INPUTS!B$26 | C48: =C43*INPUTS!C$26 | D48: =D43*INPUTS!D$26 | E48: =E43*INPUTS!E$26 | F48: =F43*INPUTS!F$26 | G48: =G43*INPUTS!G$26 | H48: =H43*INPUTS!H$26
A49: Change in NWC | B49: =B48-HISTORICALS!$K$9 | C49: =C48-B48 | D49: =D48-C48 | E49: =E48-D48 | F49: =F48-E48 | G49: =G48-F48 | H49: =H48-G48
A50: Unlevered FCF | B50: =B45+B46-B47-B49 | C50: =C45+C46-C47-C49 | D50: =D45+D46-D47-D49 | E50: =E45+E46-E47-E49 | F50: =F45+F46-F47-F49 | G50: =G45+G46-G47-G49 | H50: =H45+H46-H47-H49
A55: Column 4: Terminal growth rate = | B55: =F$4
A56: Revenue | B56: =HISTORICALS!$K$4*(1+INPUTS!B$22) | C56: =B56*(1+INPUTS!C$22) | D56: =C56*(1+INPUTS!D$22) | E56: =D56*(1+INPUTS!E$22) | F56: =E56*(1+INPUTS!F$22) | G56: =F56*(1+INPUTS!G$22) | H56: =G56*(1+INPUTS!H$22)
...

Sheet SCENARIOS
A1: SCENARIOS — bear, base and bull
A2: A parallel shift to the growth path, set by the scenario delta on INPUTS. Each case is a full projection, not a haircut to the answer.
A4: Case | B4: Growth shift | C4: Value per share
A5: Bear | B5: =-1*INPUTS!$B$19 | C5: =B23
A6: Base | B6: =0*INPUTS!$B$19 | C6: =B35
A7: Bull | B7: =1*INPUTS!$B$19 | C7: =B47
A10: Helper projections — one per case, driven off INPUTS with that case's shift applied
A12: Bear case
A13: Revenue | B13: =HISTORICALS!$K$4*(1+INPUTS!B$22+(-1*INPUTS!$B$19)) | C13: =B13*(1+INPUTS!C$22+(-1*INPUTS!$B$19)) | D13: =C13*(1+INPUTS!D$22+(-1*INPUTS!$B$19)) | E13: =D13*(1+INPUTS!E$22+(-1*INPUTS!$B$19)) | F13: =E13*(1+INPUTS!F$22+(-1*INPUTS!$B$19)) | G13: =F13*(1+INPUTS!G$22+(-1*INPUTS!$B$19)) | H13: =G13*(1+INPUTS!H$22+(-1*INPUTS!$B$19))
A14: EBIT | B14: =B13*INPUTS!B$23 | C14: =C13*INPUTS!C$23 | D14: =D13*INPUTS!D$23 | E14: =E13*INPUTS!E$23 | F14: =F13*INPUTS!F$23 | G14: =G13*INPUTS!G$23 | H14: =H13*INPUTS!H$23
A15: NOPAT | B15: =B14*(1-INPUTS!$B$4) | C15: =C14*(1-INPUTS!$B$4) | D15: =D14*(1-INPUTS!$B$4) | E15: =E14*(1-INPUTS!$B$4) | F15: =F14*(1-INPUTS!$B$4) | G15: =G14*(1-INPUTS!$B$4) | H15: =H14*(1-INPUTS!$B$4)
A16: D&A | B16: =B13*INPUTS!B$24 | C16: =C13*INPUTS!C$24 | D16: =D13*INPUTS!D$24 | E16: =E13*INPUTS!E$24 | F16: =F13*INPUTS!F$24 | G16: =G13*INPUTS!G$24 | H16: =H13*INPUTS!H$24
A17: Capex | B17: =B13*INPUTS!B$25 | C17: =C13*INPUTS!C$25 | D17: =D13*INPUTS!D$25 | E17: =E13*INPUTS!E$25 | F17: =F13*INPUTS!F$25 | G17: =G13*INPUTS!G$25 | H17: =H13*INPUTS!H$25
A18: NWC | B18: =B13*INPUTS!B$26 | C18: =C13*INPUTS!C$26 | D18: =D13*INPUTS!D$26 | E18: =E13*INPUTS!E$26 | F18: =F13*INPUTS!F$26 | G18: =G13*INPUTS!G$26 | H18: =H13*INPUTS!H$26
A19: Change in NWC | B19: =B18-HISTORICALS!$K$9 | C19: =C18-B18 | D19: =D18-C18 | E19: =E18-D18 | F19: =F18-E18 | G19: =G18-F18 | H19: =H18-G18
A20: Unlevered FCF | B20: =B15+B16-B17-B19 | C20: =C15+C16-C17-C19 | D20: =D15+D16-D17-D19 | E20: =E15+E16-E17-E19 | F20: =F15+F16-F17-F19 | G20: =G15+G16-G17-G19 | H20: =H15+H16-H17-H19
A21: PV of FCF | B21: =B20*VALUATION!B$6 | C21: =C20*VALUATION!C$6 | D21: =D20*VALUATION!D$6 | E21: =E20*VALUATION!E$6 | F21: =F20*VALUATION!F$6 | G21: =G20*VALUATION!G$6 | H21: =H20*VALUATION!H$6
A22: Enterprise value | B22: =SUM(B21:H21)+H20*(1+INPUTS!$B$11)/(INPUTS!$B$10-INPUTS!$B$11)*VALUATION!$H$6
A23: Value per share | B23: =(B22-INPUTS!$B$13)/INPUTS!$B$14
A24: Base case
A25: Revenue | B25: =HISTORICALS!$K$4*(1+INPUTS!B$22) | C25: =B25*(1+INPUTS!C$22) | D25: =C25*(1+INPUTS!D$22) | E25: =D25*(1+INPUTS!E$22) | F25: =E25*(1+INPUTS!F$22) | G25: =F25*(1+INPUTS!G$22) | H25: =G25*(1+INPUTS!H$22)
A26: EBIT | B26: =B25*INPUTS!B$23 | C26: =C25*INPUTS!C$23 | D26: =D25*INPUTS!D$23 | E26: =E25*INPUTS!E$23 | F26: =F25*INPUTS!F$23 | G26: =G25*INPUTS!G$23 | H26: =H25*INPUTS!H$23
A27: NOPAT | B27: =B26*(1-INPUTS!$B$4) | C27: =C26*(1-INPUTS!$B$4) | D27: =D26*(1-INPUTS!$B$4) | E27: =E26*(1-INPUTS!$B$4) | F27: =F26*(1-INPUTS!$B$4) | G27: =G26*(1-INPUTS!$B$4) | H27: =H26*(1-INPUTS!$B$4)
A28: D&A | B28: =B25*INPUTS!B$24 | C28: =C25*INPUTS!C$24 | D28: =D25*INPUTS!D$24 | E28: =E25*INPUTS!E$24 | F28: =F25*INPUTS!F$24 | G28: =G25*INPUTS!G$24 | H28: =H25*INPUTS!H$24
A29: Capex | B29: =B25*INPUTS!B$25 | C29: =C25*INPUTS!C$25 | D29: =D25*INPUTS!D$25 | E29: =E25*INPUTS!E$25 | F29: =F25*INPUTS!F$25 | G29: =G25*INPUTS!G$25 | H29: =H25*INPUTS!H$25
A30: NWC | B30: =B25*INPUTS!B$26 | C30: =C25*INPUTS!C$26 | D30: =D25*INPUTS!D$26 | E30: =E25*INPUTS!E$26 | F30: =F25*INPUTS!F$26 | G30: =G25*INPUTS!G$26 | H30: =H25*INPUTS!H$26
A31: Change in NWC | B31: =B30-HISTORICALS!$K$9 | C31: =C30-B30 | D31: =D30-C30 | E31: =E30-D30 | F31: =F30-E30 | G31: =G30-F30 | H31: =H30-G30
A32: Unlevered FCF | B32: =B27+B28-B29-B31 | C32: =C27+C28-C29-C31 | D32: =D27+D28-D29-D31 | E32: =E27+E28-E29-E31 | F32: =F27+F28-F29-F31 | G32: =G27+G28-G29-G31 | H32: =H27+H28-H29-H31
A33: PV of FCF | B33: =B32*VALUATION!B$6 | C33: =C32*VALUATION!C$6 | D33: =D32*VALUATION!D$6 | E33: =E32*VALUATION!E$6 | F33: =F32*VALUATION!F$6 | G33: =G32*VALUATION!G$6 | H33: =H32*VALUATION!H$6
A34: Enterprise value | B34: =SUM(B33:H33)+H32*(1+INPUTS!$B$11)/(INPUTS!$B$10-INPUTS!$B$11)*VALUATION!$H$6
A35: Value per share | B35: =(B34-INPUTS!$B$13)/INPUTS!$B$14
A36: Bull case
A37: Revenue | B37: =HISTORICALS!$K$4*(1+INPUTS!B$22+(1*INPUTS!$B$19)) | C37: =B37*(1+INPUTS!C$22+(1*INPUTS!$B$19)) | D37: =C37*(1+INPUTS!D$22+(1*INPUTS!$B$19)) | E37: =D37*(1+INPUTS!E$22+(1*INPUTS!$B$19)) | F37: =E37*(1+INPUTS!F$22+(1*INPUTS!$B$19)) | G37: =F37*(1+INPUTS!G$22+(1*INPUTS!$B$19)) | H37: =G37*(1+INPUTS!H$22+(1*INPUTS!$B$19))
A38: EBIT | B38: =B37*INPUTS!B$23 | C38: =C37*INPUTS!C$23 | D38: =D37*INPUTS!D$23 | E38: =E37*INPUTS!E$23 | F38: =F37*INPUTS!F$23 | G38: =G37*INPUTS!G$23 | H38: =H37*INPUTS!H$23
A39: NOPAT | B39: =B38*(1-INPUTS!$B$4) | C39: =C38*(1-INPUTS!$B$4) | D39: =D38*(1-INPUTS!$B$4) | E39: =E38*(1-INPUTS!$B$4) | F39: =F38*(1-INPUTS!$B$4) | G39: =G38*(1-INPUTS!$B$4) | H39: =H38*(1-INPUTS!$B$4)
A40: D&A | B40: =B37*INPUTS!B$24 | C40: =C37*INPUTS!C$24 | D40: =D37*INPUTS!D$24 | E40: =E37*INPUTS!E$24 | F40: =F37*INPUTS!F$24 | G40: =G37*INPUTS!G$24 | H40: =H37*INPUTS!H$24
A41: Capex | B41: =B37*INPUTS!B$25 | C41: =C37*INPUTS!C$25 | D41: =D37*INPUTS!D$25 | E41: =E37*INPUTS!E$25 | F41: =F37*INPUTS!F$25 | G41: =G37*INPUTS!G$25 | H41: =H37*INPUTS!H$25
A42: NWC | B42: =B37*INPUTS!B$26 | C42: =C37*INPUTS!C$26 | D42: =D37*INPUTS!D$26 | E42: =E37*INPUTS!E$26 | F42: =F37*INPUTS!F$26 | G42: =G37*INPUTS!G$26 | H42: =H37*INPUTS!H$26
A43: Change in NWC | B43: =B42-HISTORICALS!$K$9 | C43: =C42-B42 | D43: =D42-C42 | E43: =E42-D42 | F43: =F42-E42 | G43: =G42-F42 | H43: =H42-G42
A44: Unlevered FCF | B44: =B39+B40-B41-B43 | C44: =C39+C40-C41-C43 | D44: =D39+D40-D41-D43 | E44: =E39+E40-E41-E43 | F44: =F39+F40-F41-F43 | G44: =G39+G40-G41-G43 | H44: =H39+H40-H41-H43
...

Sheet FOOTBALL_FIELD
A1: FOOTBALL FIELD — every method's range on one scale
A2: A single number implies a precision none of these methods has. Where the ranges overlap is the useful part.
A4: Method | B4: Low | C4: High | D4: Width | E4: Base (for the chart)
A5: Comps — EV/Revenue | B5: =RELATIVE_PRICING!L28 | C5: =RELATIVE_PRICING!L30 | D5: =C5-B5 | E5: =B5
A6: Comps — EV/EBITDA | B6: =RELATIVE_PRICING!M28 | C6: =RELATIVE_PRICING!M30 | D6: =C6-B6 | E6: =B6
A7: Comps — P/E | B7: =RELATIVE_PRICING!N28 | C7: =RELATIVE_PRICING!N30 | D7: =C7-B7 | E7: =B7
A8: DCF — bear to bull | B8: =SCENARIOS!C5 | C8: =SCENARIOS!C7 | D8: =C8-B8 | E8: =B8
A9: DCF — WACC/growth grid | B9: =MIN(SENSITIVITY!C5:G9) | C9: =MAX(SENSITIVITY!C5:G9) | D9: =C9-B9 | E9: =B9
A10: 52-week trading range | B10: 18.9 | C10: 26.4 | D10: =C10-B10 | E10: =B10 | F10: exchange data, 2026-10-16
A12: Current share price | B12: =INPUTS!$B$15
A13: DCF base case | B13: =VALUATION!B16 | C13: Read this against the bands above, not on its own

Sheet CHECKS
A1: CHECKS — live assertions, recomputed by Excel
A2: Every row must read PASS. These recompute identities independently of the cells they test.
A3: Check | B3: Result | C3: What it proves
A4: Enterprise value ties to its components | B4: =IF(ABS(VALUATION!B12-(VALUATION!B9+VALUATION!B11))<0.01,"PASS","FAIL") | C4: EV = PV of explicit FCF + PV of terminal value
A5: Equity bridge ties | B5: =IF(ABS(VALUATION!B14-(VALUATION!B12-VALUATION!B13))<0.01,"PASS","FAIL") | C5: Equity value = EV less net debt
A6: Terminal growth below WACC | B6: =IF(INPUTS!$B$11<INPUTS!$B$10,"PASS","FAIL") | C6: The perpetuity formula converges
A7: Y1 free cash flow identity | B7: =IF(ABS(PROJECTION!B12-(PROJECTION!B7+PROJECTION!B8-PROJECTION!B9-PROJECTION!B11))<0.01,"PASS","FAIL") | C7: FCF = NOPAT + D&A - capex - change in working capital
A8: Final-year free cash flow identity | B8: =IF(ABS(PROJECTION!H12-(PROJECTION!H7+PROJECTION!H8-PROJECTION!H9-PROJECTION!H11))<0.01,"PASS","FAIL") | C8: The identity holds at the far end of the projection too
A9: Revenue growth matches the input | B9: =IF(ABS(PROJECTION!C4/PROJECTION!B4-1-INPUTS!C$22)<0.0001,"PASS","FAIL") | C9: The projection is actually driven by the growth assumption
A10: Discount factors decline | B10: =IF(VALUATION!H6<VALUATION!B6,"PASS","FAIL") | C10: Discounting runs in the right direction
A11: Sensitivity centre equals base case | B11: =IF(ABS(SENSITIVITY!E7-VALUATION!B16)<0.01,"PASS","FAIL") | C11: The grid is wired to the same model, not a separate one
A12: Share count positive | B12: =IF(INPUTS!$B$14>0,"PASS","FAIL") | C12: No divide-by-zero in per-share figures
A13: Projected margin within historical range | B13: =IF(AND(INPUTS!B23<=HISTORICALS!$B$19,INPUTS!B23>=HISTORICALS!$B$18),"PASS","REVIEW") | C13: Year-1 margin sits inside what the company has actually achieved; REVIEW means justify it, not hide it
A14: Segments reconcile to reported revenue | B14: =IF(SUMPRODUCT(MAX(ABS(SEGMENTS!B10:K10)))<0.01,"PASS","FAIL") | C14: Every reported year's segments add up to the revenue in the accounts
A15: Scenario base case equals the headline valuation | B15: =IF(ABS(SCENARIOS!C6-VALUATION!B16)<0.01,"PASS","FAIL") | C15: The bear/bull cases are re-runs of the same model, not haircuts
A16: Scenarios ordered bear < base < bull | B16: =IF(AND(SCENARIOS!C5<SCENARIOS!C6,SCENARIOS!C6<SCENARIOS!C7),"PASS","FAIL") | C16: Higher growth produces a higher value, or something is wired backwards
A17: Assumed growth at or below intrinsic growth | B17: =IF(INTRINSIC_GROWTH!B20<=INTRINSIC_GROWTH!B20,IF(INPUTS!B22<=INTRINSIC_GROWTH!B20,"PASS","REVIEW"),"REVIEW") | C17: Growth above RR x ROIC has to come from somewhere; REVIEW means say where, not hide it
A18: Exit cross-check within 50% of DCF | B18: =IF(ABS(VALUATION!B25/VALUATION!B16-1)<0.5,"PASS","REVIEW") | C18: Two terminal methods broadly agree; REVIEW means explain the gap
A20: OVERALL | B20: =IF(COUNTIF(B4:B18,"FAIL")=0,"ALL PASS","FAILURES PRESENT")
